Workbook

Sheet 1. Guide
A1: HOW TO MEASURE & GUIDE
A3: SCORING — place each dimension (A–E) at the HIGHEST LEVEL that SIMULTANEOUSLY meets the qualitative + quantitative conditions: • QUALITATIVE = Yes/No flag ticked by the auditor (MANUAL) → sheet «4. Quarterly» (orange cells). • QUANTITATIVE = measures auto-computed from raw numbers (AUTO) → enter in «3. Monthly» (yellow cells); metrics in «5. Metrics»; levels in «6. Levels». OVERALL = MIN( E-Governance , C-Quality , ROUNDED AVERAGE of the 5 dimensions ). → C and E are GATES. MANUAL minimum = exactly 2 places: raw numbers («3. Monthly») + judgment flags («4. Quarterly»). The "already-measured-or-not" flags (a1,a3,b1,b2,b3,c2,d1,d2) are AUTO-derived from data — not ticked. Codes a2/a4/b4/c3/G3… = column names in «4. Quarterly». Numeric thresholds (30/50/60/20%) are adjusted in «10. Thresholds».
A13: COLOR CONVENTIONS:
A14: YELLOW CELL — manual entry (raw numbers) | B14: GRAY CELL — auto-computed formula | C14: ORANGE CELL — Yes/No judgment flag
A16: Go to: | B16: =HYPERLINK("#'3. Monthly'!A1","3. Monthly") | C16: =HYPERLINK("#'4. Quarterly'!A1","4. Quarterly")
B17: =HYPERLINK("#'6. Levels'!A1","6. Levels") | C17: =HYPERLINK("#'8. Dashboard-Project'!A1","8. Dashboard-Project")
B18: =HYPERLINK("#'9. Dashboard-Portfolio'!A1","9. Dashboard-Portfolio") | C18: =HYPERLINK("#'7. SelfAssessment'!A1","7. SelfAssessment")
A19: LEVEL DEFINITIONS BY 2 METHODS
A20: A. ADOPTION — Is AI actually being used?
A21: Lv | B21: =HYPERLINK("#'4. Quarterly'!A1","QUALITATIVE (tick → 4. Quarterly)") | C21: =HYPERLINK("#'3. Monthly'!A1","QUANTITATIVE (auto ← 3. Monthly / 5. Metrics)")
A22: 1 | B22: Sporadic use, unclear who uses it | C22: — (a1 auto-derived: no usage numbers yet)
A23: 2 | B23: — | C23: a1 auto = usage numbers exist & usage rate ≥ 50%
A24: 3 | B24: a2 = Yes (tracking dashboard exists) | C24: AI PR % ≥ 30%
A25: 4 | B25: — (a3 auto-derived: % work assigned to agents measured) | C25: AI PR % > 50%
A26: 5 | B26: a4 = Yes (adoption near-universal, intentional) | C26: —
A28: B. DELIVERY & VALUE — Faster & more stable delivery? (DORA)
A29: Lv | B29: =HYPERLINK("#'4. Quarterly'!A1","QUALITATIVE (tick → 4. Quarterly)") | C29: =HYPERLINK("#'3. Monthly'!A1","QUANTITATIVE (auto ← 3. Monthly / 5. Metrics)")
A30: 1 | B30: Nothing measured yet | C30: —
A31: 2 | B31: — | C31: b1 auto = Deploys/week exists
A32: 3 | B32: — | C32: b2 auto (all 4 DORA) & b3 auto (cost baseline exists)
A33: 4 | B33: b4 + b5 + b6 = Yes | C33: (with 4 DORA improving — see trend)
A34: 5 | B34: b7 + b8 = Yes (regular client reporting) | C34: DORA top-quartile & stable
A36: C. QUALITY & SECURITY ★ GATE — Output correct, clean, safe?
A37: Lv | B37: =HYPERLINK("#'4. Quarterly'!A1","QUALITATIVE (tick → 4. Quarterly)") | C37: =HYPERLINK("#'3. Monthly'!A1","QUANTITATIVE (auto ← 3. Monthly / 5. Metrics)")
A38: 1 | B38: Not measured, assessed by eye | C38: —
A39: 2 | B39: Has ≥1 of: G3 / c3 | C39: c2 auto = Rework% exists
A40: 3 | B40: G3 + c3 (required review, basic scanning) | C40: c2 auto (Rework% tracked); AI PRs reviewed %
A41: 4 | B41: c4 + c5 + c6 (evals; SAST/PII required) | C41: Rework% down; Coverage up
A42: 5 | B42: c7 + c8 + c9 (prompt-leak / PII controls) | C42: Vulns & defect ≈ 0
A44: D. AGENT MATURITY — How autonomous are agents?
A45: Lv | B45: =HYPERLINK("#'4. Quarterly'!A1","QUALITATIVE (tick → 4. Quarterly)") | C45: =HYPERLINK("#'3. Monthly'!A1","QUANTITATIVE (auto ← 3. Monthly / 5. Metrics)")
A46: 1 | B46: — (d1 auto-derived: no tasks assigned to agents yet) | C46: —
A47: 2 | B47: — (d2 auto-derived: completion/intervention not measured) | C47: d1 auto = tasks assigned to agents exist
A48: 3 | B48: — | C48: d2 auto = Agent success% + Human intervention% exist
A49: 4 | B49: d3 + d4 (defined class + cycle time measured) | C49: Autonomous ≥ 30%
A50: 5 | B50: d5 + d3 + d4 (multi-agent) | C50: Autonomous ≥ 60% & Intervention ≤ 20%
A52: E. GOVERNANCE ★ GATE — Disciplined AI use? (8-item checklist)
A53: Lv | B53: =HYPERLINK("#'4. Quarterly'!A1","QUALITATIVE (tick → 4. Quarterly)") | C53: =HYPERLINK("#'3. Monthly'!A1","QUANTITATIVE (auto ← 3. Monthly / 5. Metrics)")
A54: 1 | B54: 0–1 items Yes | C54: Checklist score = 0–1 / 8
A55: 2 | B55: 2 items Yes | C55: Score = 2 / 8
...

Sheet 2. Projects
A1: PROJECT DIRECTORY
A2: ProjectID | B2: Project name | C2: Main tool | D2: Tech Lead | E2: Client / Area

Sheet 10. Thresholds
A1: LEVEL THRESHOLDS (adjustable)
A2: Parameter | B2: Value | C2: Meaning
A3: pr_L3 | B3: 0.3 | C3: Adoption L3: AI PR % ≥ 30%
A4: pr_L4 | B4: 0.5 | C4: Adoption L4: AI PR % > 50%
A5: usage_L2 | B5: 0.5 | C5: Adoption L2: AI user rate ≥ 50%
A6: aut_L4 | B6: 0.3 | C6: Agent L4: autonomous ≥ 30%
A7: aut_L5 | B7: 0.6 | C7: Agent L5: autonomous ≥ 60%
A8: int_L5 | B8: 0.2 | C8: Agent L5: intervention ≤ 20%

Sheet 3. Monthly
A1: MONTHLY RAW INPUT — enter raw numbers only (yellow cells). Percentages are in «5. Metrics».
A2: KEY | D2: A. ADOPTION (raw) | J2: B. DELIVERY (raw) | Q2: C. QUALITY (raw) | U2: D. AGENT (raw)
A3: ProjectID | B3: Month (first day) | C3: Quarter | D3: Engineers using AI/week | E3: Total engineers | F3: AI-labeled PRs | G3: Total PRs | H3: Tasks assigned to agents | I3: Total tasks | J3: Lead time (h) | K3: Deploy count | L3: Weeks | M3: Failed deploys | N3: MTTR (h) | O3: Cost baseline/unit | P3: Cost actual/unit | Q3: PR rework ≤14d | R3: AI PRs reviewed | S3: Coverage AI (%) | T3: Vulns/secrets blocked | U3: Agent tasks done OK | V3: Agent tasks needing fixes | W3: Agent end-to-end | X3: Agent cycle (h)
C4: =IF($B4="","",YEAR(B4)&"-Q"&ROUNDUP(MONTH(B4)/3,0))
C5: =IF($B5="","",YEAR(B5)&"-Q"&ROUNDUP(MONTH(B5)/3,0))
C6: =IF($B6="","",YEAR(B6)&"-Q"&ROUNDUP(MONTH(B6)/3,0))
C7: =IF($B7="","",YEAR(B7)&"-Q"&ROUNDUP(MONTH(B7)/3,0))
C8: =IF($B8="","",YEAR(B8)&"-Q"&ROUNDUP(MONTH(B8)/3,0))
C9: =IF($B9="","",YEAR(B9)&"-Q"&ROUNDUP(MONTH(B9)/3,0))
C10: =IF($B10="","",YEAR(B10)&"-Q"&ROUNDUP(MONTH(B10)/3,0))
C11: =IF($B11="","",YEAR(B11)&"-Q"&ROUNDUP(MONTH(B11)/3,0))
C12: =IF($B12="","",YEAR(B12)&"-Q"&ROUNDUP(MONTH(B12)/3,0))
C13: =IF($B13="","",YEAR(B13)&"-Q"&ROUNDUP(MONTH(B13)/3,0))
C14: =IF($B14="","",YEAR(B14)&"-Q"&ROUNDUP(MONTH(B14)/3,0))
C15: =IF($B15="","",YEAR(B15)&"-Q"&ROUNDUP(MONTH(B15)/3,0))
... C203: =IF($B203="","",YEAR(B203)&"-Q"&ROUNDUP(MONTH(B203)/3,0))

Sheet 4. Quarterly
A1: QUARTERLY SCORING — tick JUDGMENT flags only (orange cells). 'Measured' flags are derived.
A2: KEY | C2: E. GOVERNANCE — 8-item checklist | K2: A | M2: B. DELIVERY | R2: C. QUALITY | Y2: D. AGENT | AB2: EVIDENCE / ACTION
A3: ProjectID | B3: Quarter | C3: G1 AGENTS.md | D3: G2 AI policy | E3: G3 Required review | F3: G4 Eval suite | G3: G5 Shared library | H3: G6 Security controls | I3: G7 Traceability+logs | J3: G8 Model governance | K3: a2 dashboard | L3: a4 near-universal | M3: b4 DORA improving | N3: b5 cost target, many workflows | O3: b6 business outcomes | P3: b7 top-quartile | Q3: b8 client reporting | R3: c3 basic CI scanning | S3: c4 AI vs non-AI compared | T3: c5 evals exist | U3: c6 SAST/PII required | V3: c7 defects ~0 | W3: c8 evals in CI | X3: c9 prompt-leak/PII | Y3: d3 defined task class | Z3: d4 cycle time measured | AA3: d5 multi-agent | AB3: Evidence A | AC3: Evidence B | AD3: Evidence C | AE3: Evidence D | AF3: Evidence E | AG3: Improvement action
AH4: =IF($A4="","",$A4&"|"&$B4)
AH5: =IF($A5="","",$A5&"|"&$B5)
AH6: =IF($A6="","",$A6&"|"&$B6)
AH7: =IF($A7="","",$A7&"|"&$B7)
AH8: =IF($A8="","",$A8&"|"&$B8)
AH9: =IF($A9="","",$A9&"|"&$B9)
AH10: =IF($A10="","",$A10&"|"&$B10)
AH11: =IF($A11="","",$A11&"|"&$B11)
AH12: =IF($A12="","",$A12&"|"&$B12)
AH13: =IF($A13="","",$A13&"|"&$B13)
AH14: =IF($A14="","",$A14&"|"&$B14)
AH15: =IF($A15="","",$A15&"|"&$B15)
... AH53: =IF($A53="","",$A53&"|"&$B53)

Sheet 5. Metrics
A1: METRICS (auto-computed from «3. Monthly») — do not type.
A2: ProjectID | B2: Month | C2: Quarter | D2: AI usage % | E2: AI PR % | F2: %task agent | G2: Lead time(h) | H2: Deploys/week | I2: CFR % | J2: MTTR(h) | K2: Cost improvement % | L2: Rework % | M2: %PR-AI review | N2: Coverage % | O2: Vulns | P2: Agent success % | Q2: Human interv % | R2: Autonomous % | S2: Agent cycle(h)
A4: =IF('3. Monthly'!A4="","",'3. Monthly'!A4) | B4: =IF('3. Monthly'!A4="","",'3. Monthly'!B4) | C4: =IF('3. Monthly'!A4="","",'3. Monthly'!C4) | D4: =IFERROR('3. Monthly'!D4/'3. Monthly'!E4,"") | E4: =IFERROR('3. Monthly'!F4/'3. Monthly'!G4,"") | F4: =IFERROR('3. Monthly'!H4/'3. Monthly'!I4,"") | G4: =IF('3. Monthly'!J4="","",'3. Monthly'!J4) | H4: =IFERROR('3. Monthly'!K4/'3. Monthly'!L4,"") | I4: =IFERROR('3. Monthly'!M4/'3. Monthly'!K4,"") | J4: =IF('3. Monthly'!N4="","",'3. Monthly'!N4) | K4: =IFERROR(('3. Monthly'!O4-'3. Monthly'!P4)/'3. Monthly'!O4,"") | L4: =IFERROR('3. Monthly'!Q4/'3. Monthly'!G4,"") | M4: =IFERROR('3. Monthly'!R4/'3. Monthly'!F4,"") | N4: =IF('3. Monthly'!S4="","",'3. Monthly'!S4) | O4: =IF('3. Monthly'!T4="","",'3. Monthly'!T4) | P4: =IFERROR('3. Monthly'!U4/'3. Monthly'!H4,"") | Q4: =IFERROR('3. Monthly'!V4/'3. Monthly'!H4,"") | R4: =IFERROR('3. Monthly'!W4/'3. Monthly'!H4,"") | S4: =IF('3. Monthly'!X4="","",'3. Monthly'!X4)
A5: =IF('3. Monthly'!A5="","",'3. Monthly'!A5) | B5: =IF('3. Monthly'!A5="","",'3. Monthly'!B5) | C5: =IF('3. Monthly'!A5="","",'3. Monthly'!C5) | D5: =IFERROR('3. Monthly'!D5/'3. Monthly'!E5,"") | E5: =IFERROR('3. Monthly'!F5/'3. Monthly'!G5,"") | F5: =IFERROR('3. Monthly'!H5/'3. Monthly'!I5,"") | G5: =IF('3. Monthly'!J5="","",'3. Monthly'!J5) | H5: =IFERROR('3. Monthly'!K5/'3. Monthly'!L5,"") | I5: =IFERROR('3. Monthly'!M5/'3. Monthly'!K5,"") | J5: =IF('3. Monthly'!N5="","",'3. Monthly'!N5) | K5: =IFERROR(('3. Monthly'!O5-'3. Monthly'!P5)/'3. Monthly'!O5,"") | L5: =IFERROR('3. Monthly'!Q5/'3. Monthly'!G5,"") | M5: =IFERROR('3. Monthly'!R5/'3. Monthly'!F5,"") | N5: =IF('3. Monthly'!S5="","",'3. Monthly'!S5) | O5: =IF('3. Monthly'!T5="","",'3. Monthly'!T5) | P5: =IFERROR('3. Monthly'!U5/'3. Monthly'!H5,"") | Q5: =IFERROR('3. Monthly'!V5/'3. Monthly'!H5,"") | R5: =IFERROR('3. Monthly'!W5/'3. Monthly'!H5,"") | S5: =IF('3. Monthly'!X5="","",'3. Monthly'!X5)
A6: =IF('3. Monthly'!A6="","",'3. Monthly'!A6) | B6: =IF('3. Monthly'!A6="","",'3. Monthly'!B6) | C6: =IF('3. Monthly'!A6="","",'3. Monthly'!C6) | D6: =IFERROR('3. Monthly'!D6/'3. Monthly'!E6,"") | E6: =IFERROR('3. Monthly'!F6/'3. Monthly'!G6,"") | F6: =IFERROR('3. Monthly'!H6/'3. Monthly'!I6,"") | G6: =IF('3. Monthly'!J6="","",'3. Monthly'!J6) | H6: =IFERROR('3. Monthly'!K6/'3. Monthly'!L6,"") | I6: =IFERROR('3. Monthly'!M6/'3. Monthly'!K6,"") | J6: =IF('3. Monthly'!N6="","",'3. Monthly'!N6) | K6: =IFERROR(('3. Monthly'!O6-'3. Monthly'!P6)/'3. Monthly'!O6,"") | L6: =IFERROR('3. Monthly'!Q6/'3. Monthly'!G6,"") | M6: =IFERROR('3. Monthly'!R6/'3. Monthly'!F6,"") | N6: =IF('3. Monthly'!S6="","",'3. Monthly'!S6) | O6: =IF('3. Monthly'!T6="","",'3. Monthly'!T6) | P6: =IFERROR('3. Monthly'!U6/'3. Monthly'!H6,"") | Q6: =IFERROR('3. Monthly'!V6/'3. Monthly'!H6,"") | R6: =IFERROR('3. Monthly'!W6/'3. Monthly'!H6,"") | S6: =IF('3. Monthly'!X6="","",'3. Monthly'!X6)
A7: =IF('3. Monthly'!A7="","",'3. Monthly'!A7) | B7: =IF('3. Monthly'!A7="","",'3. Monthly'!B7) | C7: =IF('3. Monthly'!A7="","",'3. Monthly'!C7) | D7: =IFERROR('3. Monthly'!D7/'3. Monthly'!E7,"") | E7: =IFERROR('3. Monthly'!F7/'3. Monthly'!G7,"") | F7: =IFERROR('3. Monthly'!H7/'3. Monthly'!I7,"") | G7: =IF('3. Monthly'!J7="","",'3. Monthly'!J7) | H7: =IFERROR('3. Monthly'!K7/'3. Monthly'!L7,"") | I7: =IFERROR('3. Monthly'!M7/'3. Monthly'!K7,"") | J7: =IF('3. Monthly'!N7="","",'3. Monthly'!N7) | K7: =IFERROR(('3. Monthly'!O7-'3. Monthly'!P7)/'3. Monthly'!O7,"") | L7: =IFERROR('3. Monthly'!Q7/'3. Monthly'!G7,"") | M7: =IFERROR('3. Monthly'!R7/'3. Monthly'!F7,"") | N7: =IF('3. Monthly'!S7="","",'3. Monthly'!S7) | O7: =IF('3. Monthly'!T7="","",'3. Monthly'!T7) | P7: =IFERROR('3. Monthly'!U7/'3. Monthly'!H7,"") | Q7: =IFERROR('3. Monthly'!V7/'3. Monthly'!H7,"") | R7: =IFERROR('3. Monthly'!W7/'3. Monthly'!H7,"") | S7: =IF('3. Monthly'!X7="","",'3. Monthly'!X7)
A8: =IF('3. Monthly'!A8="","",'3. Monthly'!A8) | B8: =IF('3. Monthly'!A8="","",'3. Monthly'!B8) | C8: =IF('3. Monthly'!A8="","",'3. Monthly'!C8) | D8: =IFERROR('3. Monthly'!D8/'3. Monthly'!E8,"") | E8: =IFERROR('3. Monthly'!F8/'3. Monthly'!G8,"") | F8: =IFERROR('3. Monthly'!H8/'3. Monthly'!I8,"") | G8: =IF('3. Monthly'!J8="","",'3. Monthly'!J8) | H8: =IFERROR('3. Monthly'!K8/'3. Monthly'!L8,"") | I8: =IFERROR('3. Monthly'!M8/'3. Monthly'!K8,"") | J8: =IF('3. Monthly'!N8="","",'3. Monthly'!N8) | K8: =IFERROR(('3. Monthly'!O8-'3. Monthly'!P8)/'3. Monthly'!O8,"") | L8: =IFERROR('3. Monthly'!Q8/'3. Monthly'!G8,"") | M8: =IFERROR('3. Monthly'!R8/'3. Monthly'!F8,"") | N8: =IF('3. Monthly'!S8="","",'3. Monthly'!S8) | O8: =IF('3. Monthly'!T8="","",'3. Monthly'!T8) | P8: =IFERROR('3. Monthly'!U8/'3. Monthly'!H8,"") | Q8: =IFERROR('3. Monthly'!V8/'3. Monthly'!H8,"") | R8: =IFERROR('3. Monthly'!W8/'3. Monthly'!H8,"") | S8: =IF('3. Monthly'!X8="","",'3. Monthly'!X8)
A9: =IF('3. Monthly'!A9="","",'3. Monthly'!A9) | B9: =IF('3. Monthly'!A9="","",'3. Monthly'!B9) | C9: =IF('3. Monthly'!A9="","",'3. Monthly'!C9) | D9: =IFERROR('3. Monthly'!D9/'3. Monthly'!E9,"") | E9: =IFERROR('3. Monthly'!F9/'3. Monthly'!G9,"") | F9: =IFERROR('3. Monthly'!H9/'3. Monthly'!I9,"") | G9: =IF('3. Monthly'!J9="","",'3. Monthly'!J9) | H9: =IFERROR('3. Monthly'!K9/'3. Monthly'!L9,"") | I9: =IFERROR('3. Monthly'!M9/'3. Monthly'!K9,"") | J9: =IF('3. Monthly'!N9="","",'3. Monthly'!N9) | K9: =IFERROR(('3. Monthly'!O9-'3. Monthly'!P9)/'3. Monthly'!O9,"") | L9: =IFERROR('3. Monthly'!Q9/'3. Monthly'!G9,"") | M9: =IFERROR('3. Monthly'!R9/'3. Monthly'!F9,"") | N9: =IF('3. Monthly'!S9="","",'3. Monthly'!S9) | O9: =IF('3. Monthly'!T9="","",'3. Monthly'!T9) | P9: =IFERROR('3. Monthly'!U9/'3. Monthly'!H9,"") | Q9: =IFERROR('3. Monthly'!V9/'3. Monthly'!H9,"") | R9: =IFERROR('3. Monthly'!W9/'3. Monthly'!H9,"") | S9: =IF('3. Monthly'!X9="","",'3. Monthly'!X9)
A10: =IF('3. Monthly'!A10="","",'3. Monthly'!A10) | B10: =IF('3. Monthly'!A10="","",'3. Monthly'!B10) | C10: =IF('3. Monthly'!A10="","",'3. Monthly'!C10) | D10: =IFERROR('3. Monthly'!D10/'3. Monthly'!E10,"") | E10: =IFERROR('3. Monthly'!F10/'3. Monthly'!G10,"") | F10: =IFERROR('3. Monthly'!H10/'3. Monthly'!I10,"") | G10: =IF('3. Monthly'!J10="","",'3. Monthly'!J10) | H10: =IFERROR('3. Monthly'!K10/'3. Monthly'!L10,"") | I10: =IFERROR('3. Monthly'!M10/'3. Monthly'!K10,"") | J10: =IF('3. Monthly'!N10="","",'3. Monthly'!N10) | K10: =IFERROR(('3. Monthly'!O10-'3. Monthly'!P10)/'3. Monthly'!O10,"") | L10: =IFERROR('3. Monthly'!Q10/'3. Monthly'!G10,"") | M10: =IFERROR('3. Monthly'!R10/'3. Monthly'!F10,"") | N10: =IF('3. Monthly'!S10="","",'3. Monthly'!S10) | O10: =IF('3. Monthly'!T10="","",'3. Monthly'!T10) | P10: =IFERROR('3. Monthly'!U10/'3. Monthly'!H10,"") | Q10: =IFERROR('3. Monthly'!V10/'3. Monthly'!H10,"") | R10: =IFERROR('3. Monthly'!W10/'3. Monthly'!H10,"") | S10: =IF('3. Monthly'!X10="","",'3. Monthly'!X10)
A11: =IF('3. Monthly'!A11="","",'3. Monthly'!A11) | B11: =IF('3. Monthly'!A11="","",'3. Monthly'!B11) | C11: =IF('3. Monthly'!A11="","",'3. Monthly'!C11) | D11: =IFERROR('3. Monthly'!D11/'3. Monthly'!E11,"") | E11: =IFERROR('3. Monthly'!F11/'3. Monthly'!G11,"") | F11: =IFERROR('3. Monthly'!H11/'3. Monthly'!I11,"") | G11: =IF('3. Monthly'!J11="","",'3. Monthly'!J11) | H11: =IFERROR('3. Monthly'!K11/'3. Monthly'!L11,"") | I11: =IFERROR('3. Monthly'!M11/'3. Monthly'!K11,"") | J11: =IF('3. Monthly'!N11="","",'3. Monthly'!N11) | K11: =IFERROR(('3. Monthly'!O11-'3. Monthly'!P11)/'3. Monthly'!O11,"") | L11: =IFERROR('3. Monthly'!Q11/'3. Monthly'!G11,"") | M11: =IFERROR('3. Monthly'!R11/'3. Monthly'!F11,"") | N11: =IF('3. Monthly'!S11="","",'3. Monthly'!S11) | O11: =IF('3. Monthly'!T11="","",'3. Monthly'!T11) | P11: =IFERROR('3. Monthly'!U11/'3. Monthly'!H11,"") | Q11: =IFERROR('3. Monthly'!V11/'3. Monthly'!H11,"") | R11: =IFERROR('3. Monthly'!W11/'3. Monthly'!H11,"") | S11: =IF('3. Monthly'!X11="","",'3. Monthly'!X11)
A12: =IF('3. Monthly'!A12="","",'3. Monthly'!A12) | B12: =IF('3. Monthly'!A12="","",'3. Monthly'!B12) | C12: =IF('3. Monthly'!A12="","",'3. Monthly'!C12) | D12: =IFERROR('3. Monthly'!D12/'3. Monthly'!E12,"") | E12: =IFERROR('3. Monthly'!F12/'3. Monthly'!G12,"") | F12: =IFERROR('3. Monthly'!H12/'3. Monthly'!I12,"") | G12: =IF('3. Monthly'!J12="","",'3. Monthly'!J12) | H12: =IFERROR('3. Monthly'!K12/'3. Monthly'!L12,"") | I12: =IFERROR('3. Monthly'!M12/'3. Monthly'!K12,"") | J12: =IF('3. Monthly'!N12="","",'3. Monthly'!N12) | K12: =IFERROR(('3. Monthly'!O12-'3. Monthly'!P12)/'3. Monthly'!O12,"") | L12: =IFERROR('3. Monthly'!Q12/'3. Monthly'!G12,"") | M12: =IFERROR('3. Monthly'!R12/'3. Monthly'!F12,"") | N12: =IF('3. Monthly'!S12="","",'3. Monthly'!S12) | O12: =IF('3. Monthly'!T12="","",'3. Monthly'!T12) | P12: =IFERROR('3. Monthly'!U12/'3. Monthly'!H12,"") | Q12: =IFERROR('3. Monthly'!V12/'3. Monthly'!H12,"") | R12: =IFERROR('3. Monthly'!W12/'3. Monthly'!H12,"") | S12: =IF('3. Monthly'!X12="","",'3. Monthly'!X12)
A13: =IF('3. Monthly'!A13="","",'3. Monthly'!A13) | B13: =IF('3. Monthly'!A13="","",'3. Monthly'!B13) | C13: =IF('3. Monthly'!A13="","",'3. Monthly'!C13) | D13: =IFERROR('3. Monthly'!D13/'3. Monthly'!E13,"") | E13: =IFERROR('3. Monthly'!F13/'3. Monthly'!G13,"") | F13: =IFERROR('3. Monthly'!H13/'3. Monthly'!I13,"") | G13: =IF('3. Monthly'!J13="","",'3. Monthly'!J13) | H13: =IFERROR('3. Monthly'!K13/'3. Monthly'!L13,"") | I13: =IFERROR('3. Monthly'!M13/'3. Monthly'!K13,"") | J13: =IF('3. Monthly'!N13="","",'3. Monthly'!N13) | K13: =IFERROR(('3. Monthly'!O13-'3. Monthly'!P13)/'3. Monthly'!O13,"") | L13: =IFERROR('3. Monthly'!Q13/'3. Monthly'!G13,"") | M13: =IFERROR('3. Monthly'!R13/'3. Monthly'!F13,"") | N13: =IF('3. Monthly'!S13="","",'3. Monthly'!S13) | O13: =IF('3. Monthly'!T13="","",'3. Monthly'!T13) | P13: =IFERROR('3. Monthly'!U13/'3. Monthly'!H13,"") | Q13: =IFERROR('3. Monthly'!V13/'3. Monthly'!H13,"") | R13: =IFERROR('3. Monthly'!W13/'3. Monthly'!H13,"") | S13: =IF('3. Monthly'!X13="","",'3. Monthly'!X13)
A14: =IF('3. Monthly'!A14="","",'3. Monthly'!A14) | B14: =IF('3. Monthly'!A14="","",'3. Monthly'!B14) | C14: =IF('3. Monthly'!A14="","",'3. Monthly'!C14) | D14: =IFERROR('3. Monthly'!D14/'3. Monthly'!E14,"") | E14: =IFERROR('3. Monthly'!F14/'3. Monthly'!G14,"") | F14: =IFERROR('3. Monthly'!H14/'3. Monthly'!I14,"") | G14: =IF('3. Monthly'!J14="","",'3. Monthly'!J14) | H14: =IFERROR('3. Monthly'!K14/'3. Monthly'!L14,"") | I14: =IFERROR('3. Monthly'!M14/'3. Monthly'!K14,"") | J14: =IF('3. Monthly'!N14="","",'3. Monthly'!N14) | K14: =IFERROR(('3. Monthly'!O14-'3. Monthly'!P14)/'3. Monthly'!O14,"") | L14: =IFERROR('3. Monthly'!Q14/'3. Monthly'!G14,"") | M14: =IFERROR('3. Monthly'!R14/'3. Monthly'!F14,"") | N14: =IF('3. Monthly'!S14="","",'3. Monthly'!S14) | O14: =IF('3. Monthly'!T14="","",'3. Monthly'!T14) | P14: =IFERROR('3. Monthly'!U14/'3. Monthly'!H14,"") | Q14: =IFERROR('3. Monthly'!V14/'3. Monthly'!H14,"") | R14: =IFERROR('3. Monthly'!W14/'3. Monthly'!H14,"") | S14: =IF('3. Monthly'!X14="","",'3. Monthly'!X14)
A15: =IF('3. Monthly'!A15="","",'3. Monthly'!A15) | B15: =IF('3. Monthly'!A15="","",'3. Monthly'!B15) | C15: =IF('3. Monthly'!A15="","",'3. Monthly'!C15) | D15: =IFERROR('3. Monthly'!D15/'3. Monthly'!E15,"") | E15: =IFERROR('3. Monthly'!F15/'3. Monthly'!G15,"") | F15: =IFERROR('3. Monthly'!H15/'3. Monthly'!I15,"") | G15: =IF('3. Monthly'!J15="","",'3. Monthly'!J15) | H15: =IFERROR('3. Monthly'!K15/'3. Monthly'!L15,"") | I15: =IFERROR('3. Monthly'!M15/'3. Monthly'!K15,"") | J15: =IF('3. Monthly'!N15="","",'3. Monthly'!N15) | K15: =IFERROR(('3. Monthly'!O15-'3. Monthly'!P15)/'3. Monthly'!O15,"") | L15: =IFERROR('3. Monthly'!Q15/'3. Monthly'!G15,"") | M15: =IFERROR('3. Monthly'!R15/'3. Monthly'!F15,"") | N15: =IF('3. Monthly'!S15="","",'3. Monthly'!S15) | O15: =IF('3. Monthly'!T15="","",'3. Monthly'!T15) | P15: =IFERROR('3. Monthly'!U15/'3. Monthly'!H15,"") | Q15: =IFERROR('3. Monthly'!V15/'3. Monthly'!H15,"") | R15: =IFERROR('3. Monthly'!W15/'3. Monthly'!H15,"") | S15: =IF('3. Monthly'!X15="","",'3. Monthly'!X15)
... A203: =IF('3. Monthly'!A203="","",'3. Monthly'!A203) | B203: =IF('3. Monthly'!A203="","",'3. Monthly'!B203) | C203: =IF('3. Monthly'!A203="","",'3. Monthly'!C203) | D203: =IFERROR('3. Monthly'!D203/'3. Monthly'!E203,"") | E203: =IFERROR('3. Monthly'!F203/'3. Monthly'!G203,"") | F203: =IFERROR('3. Monthly'!H203/'3. Monthly'!I203,"") | G203: =IF('3. Monthly'!J203="","",'3. Monthly'!J203) | H203: =IFERROR('3. Monthly'!K203/'3. Monthly'!L203,"") | I203: =IFERROR('3. Monthly'!M203/'3. Monthly'!K203,"") | J203: =IF('3. Monthly'!N203="","",'3. Monthly'!N203) | K203: =IFERROR(('3. Monthly'!O203-'3. Monthly'!P203)/'3. Monthly'!O203,"") | L203: =IFERROR('3. Monthly'!Q203/'3. Monthly'!G203,"") | M203: =IFERROR('3. Monthly'!R203/'3. Monthly'!F203,"") | N203: =IF('3. Monthly'!S203="","",'3. Monthly'!S203) | O203: =IF('3. Monthly'!T203="","",'3. Monthly'!T203) | P203: =IFERROR('3. Monthly'!U203/'3. Monthly'!H203,"") | Q203: =IFERROR('3. Monthly'!V203/'3. Monthly'!H203,"") | R203: =IFERROR('3. Monthly'!W203/'3. Monthly'!H203,"") | S203: =IF('3. Monthly'!X203="","",'3. Monthly'!X203)

Sheet 6. Levels
A1: LEVEL MAPPING (auto) — looked up by key ProjectID+Quarter. Do not type.
A3: ProjectID | B3: Quarter | C3: Project name | D3: AI usage% | E3: %PR-AI | F3: %agent | G3: CFR% | H3: Rework% | I3: %AI review | J3: Coverage% | K3: Agent succ% | L3: Human interv% | M3: Autonomous% | N3: A | O3: B | P3: C | Q3: D | R3: E | S3: OVERALL | T3: Key | U3: a1 | V3: a3 | W3: b1 | X3: b2 | Y3: b3 | Z3: c2 | AA3: d1 | AB3: d2
A4: ='4. Quarterly'!A4 | B4: ='4. Quarterly'!B4 | C4: =IFERROR(VLOOKUP($A4,'2. Projects'!$A$3:$B$20,2,0),"") | D4: =IF($A4="","",IFERROR(AVERAGEIFS('5. Metrics'!$D$4:$D$203,'5. Metrics'!$A$4:$A$203,$A4,'5. Metrics'!$C$4:$C$203,$B4),"")) | E4: =IF($A4="","",IFERROR(AVERAGEIFS('5. Metrics'!$E$4:$E$203,'5. Metrics'!$A$4:$A$203,$A4,'5. Metrics'!$C$4:$C$203,$B4),"")) | F4: =IF($A4="","",IFERROR(AVERAGEIFS('5. Metrics'!$F$4:$F$203,'5. Metrics'!$A$4:$A$203,$A4,'5. Metrics'!$C$4:$C$203,$B4),"")) | G4: =IF($A4="","",IFERROR(AVERAGEIFS('5. Metrics'!$I$4:$I$203,'5. Metrics'!$A$4:$A$203,$A4,'5. Metrics'!$C$4:$C$203,$B4),"")) | H4: =IF($A4="","",IFERROR(AVERAGEIFS('5. Metrics'!$L$4:$L$203,'5. Metrics'!$A$4:$A$203,$A4,'5. Metrics'!$C$4:$C$203,$B4),"")) | I4: =IF($A4="","",IFERROR(AVERAGEIFS('5. Metrics'!$M$4:$M$203,'5. Metrics'!$A$4:$A$203,$A4,'5. Metrics'!$C$4:$C$203,$B4),"")) | J4: =IF($A4="","",IFERROR(AVERAGEIFS('5. Metrics'!$N$4:$N$203,'5. Metrics'!$A$4:$A$203,$A4,'5. Metrics'!$C$4:$C$203,$B4),"")) | K4: =IF($A4="","",IFERROR(AVERAGEIFS('5. Metrics'!$P$4:$P$203,'5. Metrics'!$A$4:$A$203,$A4,'5. Metrics'!$C$4:$C$203,$B4),"")) | L4: =IF($A4="","",IFERROR(AVERAGEIFS('5. Metrics'!$Q$4:$Q$203,'5. Metrics'!$A$4:$A$203,$A4,'5. Metrics'!$C$4:$C$203,$B4),"")) | M4: =IF($A4="","",IFERROR(AVERAGEIFS('5. Metrics'!$R$4:$R$203,'5. Metrics'!$A$4:$A$203,$A4,'5. Metrics'!$C$4:$C$203,$B4),"")) | N4: =IF($A4="","",IF('4. Quarterly'!L4="Yes",5,IF(AND(ISNUMBER(E4),E4>'10. Thresholds'!$B$4,V4="Yes"),4,IF(AND('4. Quarterly'!K4="Yes",ISNUMBER(E4),E4>='10. Thresholds'!$B$3),3,IF(AND(U4="Yes",ISNUMBER(D4),D4>='10. Thresholds'!$B$5),2,1))))) | O4: =IF($A4="","",IF(AND('4. Quarterly'!P4="Yes",'4. Quarterly'!Q4="Yes",'4. Quarterly'!M4="Yes",'4. Quarterly'!N4="Yes",'4. Quarterly'!O4="Yes",X4="Yes",Y4="Yes"),5,IF(AND('4. Quarterly'!M4="Yes",'4. Quarterly'!N4="Yes",'4. Quarterly'!O4="Yes",X4="Yes",Y4="Yes"),4,IF(AND(X4="Yes",Y4="Yes"),3,IF(W4="Yes",2,1))))) | P4: =IF($A4="","",IF(AND('4. Quarterly'!V4="Yes",'4. Quarterly'!W4="Yes",'4. Quarterly'!X4="Yes",'4. Quarterly'!S4="Yes",'4. Quarterly'!T4="Yes",'4. Quarterly'!U4="Yes",'4. Quarterly'!E4="Yes",Z4="Yes",'4. Quarterly'!R4="Yes"),5,IF(AND('4. Quarterly'!S4="Yes",'4. Quarterly'!T4="Yes",'4. Quarterly'!U4="Yes",'4. Quarterly'!E4="Yes",Z4="Yes",'4. Quarterly'!R4="Yes"),4,IF(AND('4. Quarterly'!E4="Yes",Z4="Yes",'4. Quarterly'!R4="Yes"),3,IF(OR(Z4="Yes",'4. Quarterly'!R4="Yes",'4. Quarterly'!E4="Yes"),2,1))))) | Q4: =IF($A4="","",IF(AA4<>"Yes",1,IF(AB4<>"Yes",2,IF(AND('4. Quarterly'!AA4="Yes",'4. Quarterly'!Y4="Yes",'4. Quarterly'!Z4="Yes",ISNUMBER(M4),M4>='10. Thresholds'!$B$7,ISNUMBER(L4),L4<='10. Thresholds'!$B$8),5,IF(AND('4. Quarterly'!Y4="Yes",'4. Quarterly'!Z4="Yes",ISNUMBER(M4),M4>='10. Thresholds'!$B$6),4,3))))) | R4: =IF($A4="","",IF(AND('4. Quarterly'!C4="Yes",'4. Quarterly'!D4="Yes",'4. Quarterly'!E4="Yes",'4. Quarterly'!F4="Yes",'4. Quarterly'!G4="Yes",'4. Quarterly'!H4="Yes",'4. Quarterly'!I4="Yes",'4. Quarterly'!J4="Yes"),5,IF(AND('4. Quarterly'!C4="Yes",'4. Quarterly'!D4="Yes",'4. Quarterly'!E4="Yes",'4. Quarterly'!F4="Yes",'4. Quarterly'!G4="Yes"),4,IF(AND('4. Quarterly'!C4="Yes",'4. Quarterly'!D4="Yes",'4. Quarterly'!E4="Yes"),3,IF(COUNTIF('4. Quarterly'!C4:J4,"Yes")>=2,2,1))))) | S4: =IF($A4="","",MIN(R4,P4,ROUND(AVERAGE(N4,O4,P4,Q4,R4),0))) | T4: =IF($A4="","",$A4&"|"&$B4) | U4: =IF($A4="","No",IF(COUNTIFS('3. Monthly'!$A$4:$A$203,$A4,'3. Monthly'!$C$4:$C$203,$B4,'3. Monthly'!$E$4:$E$203,">0")>0,"Yes","No")) | V4: =IF($A4="","No",IF(COUNTIFS('3. Monthly'!$A$4:$A$203,$A4,'3. Monthly'!$C$4:$C$203,$B4,'3. Monthly'!$I$4:$I$203,">0")>0,"Yes","No")) | W4: =IF($A4="","No",IF(COUNTIFS('3. Monthly'!$A$4:$A$203,$A4,'3. Monthly'!$C$4:$C$203,$B4,'3. Monthly'!$K$4:$K$203,">=0",'3. Monthly'!$L$4:$L$203,">0")>0,"Yes","No")) | X4: =IF($A4="","No",IF(COUNTIFS('3. Monthly'!$A$4:$A$203,$A4,'3. Monthly'!$C$4:$C$203,$B4,'3. Monthly'!$J$4:$J$203,">=0",'3. Monthly'!$K$4:$K$203,">=0",'3. Monthly'!$M$4:$M$203,">=0",'3. Monthly'!$N$4:$N$203,">=0",'3. Monthly'!$L$4:$L$203,">0")>0,"Yes","No")) | Y4: =IF($A4="","No",IF(COUNTIFS('3. Monthly'!$A$4:$A$203,$A4,'3. Monthly'!$C$4:$C$203,$B4,'3. Monthly'!$O$4:$O$203,">0")>0,"Yes","No")) | Z4: =IF($A4="","No",IF(COUNTIFS('3. Monthly'!$A$4:$A$203,$A4,'3. Monthly'!$C$4:$C$203,$B4,'3. Monthly'!$Q$4:$Q$203,">=0",'3. Monthly'!$G$4:$G$203,">0")>0,"Yes","No")) | AA4: =IF($A4="","No",IF(COUNTIFS('3. Monthly'!$A$4:$A$203,$A4,'3. Monthly'!$C$4:$C$203,$B4,'3. Monthly'!$H$4:$H$203,">0")>0,"Yes","No")) | AB4: =IF($A4="","No",IF(COUNTIFS('3. Monthly'!$A$4:$A$203,$A4,'3. Monthly'!$C$4:$C$203,$B4,'3. Monthly'!$U$4:$U$203,">=0",'3. Monthly'!$V$4:$V$203,">=0",'3. Monthly'!$H$4:$H$203,">0")>0,"Yes","No"))
A5: ='4. Quarterly'!A5 | B5: ='4. Quarterly'!B5 | C5: =IFERROR(VLOOKUP($A5,'2. Projects'!$A$3:$B$20,2,0),"") | D5: =IF($A5="","",IFERROR(AVERAGEIFS('5. Metrics'!$D$4:$D$203,'5. Metrics'!$A$4:$A$203,$A5,'5. Metrics'!$C$4:$C$203,$B5),"")) | E5: =IF($A5="","",IFERROR(AVERAGEIFS('5. Metrics'!$E$4:$E$203,'5. Metrics'!$A$4:$A$203,$A5,'5. Metrics'!$C$4:$C$203,$B5),"")) | F5: =IF($A5="","",IFERROR(AVERAGEIFS('5. Metrics'!$F$4:$F$203,'5. Metrics'!$A$4:$A$203,$A5,'5. Metrics'!$C$4:$C$203,$B5),"")) | G5: =IF($A5="","",IFERROR(AVERAGEIFS('5. Metrics'!$I$4:$I$203,'5. Metrics'!$A$4:$A$203,$A5,'5. Metrics'!$C$4:$C$203,$B5),"")) | H5: =IF($A5="","",IFERROR(AVERAGEIFS('5. Metrics'!$L$4:$L$203,'5. Metrics'!$A$4:$A$203,$A5,'5. Metrics'!$C$4:$C$203,$B5),"")) | I5: =IF($A5="","",IFERROR(AVERAGEIFS('5. Metrics'!$M$4:$M$203,'5. Metrics'!$A$4:$A$203,$A5,'5. Metrics'!$C$4:$C$203,$B5),"")) | J5: =IF($A5="","",IFERROR(AVERAGEIFS('5. Metrics'!$N$4:$N$203,'5. Metrics'!$A$4:$A$203,$A5,'5. Metrics'!$C$4:$C$203,$B5),"")) | K5: =IF($A5="","",IFERROR(AVERAGEIFS('5. Metrics'!$P$4:$P$203,'5. Metrics'!$A$4:$A$203,$A5,'5. Metrics'!$C$4:$C$203,$B5),"")) | L5: =IF($A5="","",IFERROR(AVERAGEIFS('5. Metrics'!$Q$4:$Q$203,'5. Metrics'!$A$4:$A$203,$A5,'5. Metrics'!$C$4:$C$203,$B5),"")) | M5: =IF($A5="","",IFERROR(AVERAGEIFS('5. Metrics'!$R$4:$R$203,'5. Metrics'!$A$4:$A$203,$A5,'5. Metrics'!$C$4:$C$203,$B5),"")) | N5: =IF($A5="","",IF('4. Quarterly'!L5="Yes",5,IF(AND(ISNUMBER(E5),E5>'10. Thresholds'!$B$4,V5="Yes"),4,IF(AND('4. Quarterly'!K5="Yes",ISNUMBER(E5),E5>='10. Thresholds'!$B$3),3,IF(AND(U5="Yes",ISNUMBER(D5),D5>='10. Thresholds'!$B$5),2,1))))) | O5: =IF($A5="","",IF(AND('4. Quarterly'!P5="Yes",'4. Quarterly'!Q5="Yes",'4. Quarterly'!M5="Yes",'4. Quarterly'!N5="Yes",'4. Quarterly'!O5="Yes",X5="Yes",Y5="Yes"),5,IF(AND('4. Quarterly'!M5="Yes",'4. Quarterly'!N5="Yes",'4. Quarterly'!O5="Yes",X5="Yes",Y5="Yes"),4,IF(AND(X5="Yes",Y5="Yes"),3,IF(W5="Yes",2,1))))) | P5: =IF($A5="","",IF(AND('4. Quarterly'!V5="Yes",'4. Quarterly'!W5="Yes",'4. Quarterly'!X5="Yes",'4. Quarterly'!S5="Yes",'4. Quarterly'!T5="Yes",'4. Quarterly'!U5="Yes",'4. Quarterly'!E5="Yes",Z5="Yes",'4. Quarterly'!R5="Yes"),5,IF(AND('4. Quarterly'!S5="Yes",'4. Quarterly'!T5="Yes",'4. Quarterly'!U5="Yes",'4. Quarterly'!E5="Yes",Z5="Yes",'4. Quarterly'!R5="Yes"),4,IF(AND('4. Quarterly'!E5="Yes",Z5="Yes",'4. Quarterly'!R5="Yes"),3,IF(OR(Z5="Yes",'4. Quarterly'!R5="Yes",'4. Quarterly'!E5="Yes"),2,1))))) | Q5: =IF($A5="","",IF(AA5<>"Yes",1,IF(AB5<>"Yes",2,IF(AND('4. Quarterly'!AA5="Yes",'4. Quarterly'!Y5="Yes",'4. Quarterly'!Z5="Yes",ISNUMBER(M5),M5>='10. Thresholds'!$B$7,ISNUMBER(L5),L5<='10. Thresholds'!$B$8),5,IF(AND('4. Quarterly'!Y5="Yes",'4. Quarterly'!Z5="Yes",ISNUMBER(M5),M5>='10. Thresholds'!$B$6),4,3))))) | R5: =IF($A5="","",IF(AND('4. Quarterly'!C5="Yes",'4. Quarterly'!D5="Yes",'4. Quarterly'!E5="Yes",'4. Quarterly'!F5="Yes",'4. Quarterly'!G5="Yes",'4. Quarterly'!H5="Yes",'4. Quarterly'!I5="Yes",'4. Quarterly'!J5="Yes"),5,IF(AND('4. Quarterly'!C5="Yes",'4. Quarterly'!D5="Yes",'4. Quarterly'!E5="Yes",'4. Quarterly'!F5="Yes",'4. Quarterly'!G5="Yes"),4,IF(AND('4. Quarterly'!C5="Yes",'4. Quarterly'!D5="Yes",'4. Quarterly'!E5="Yes"),3,IF(COUNTIF('4. Quarterly'!C5:J5,"Yes")>=2,2,1))))) | S5: =IF($A5="","",MIN(R5,P5,ROUND(AVERAGE(N5,O5,P5,Q5,R5),0))) | T5: =IF($A5="","",$A5&"|"&$B5) | U5: =IF($A5="","No",IF(COUNTIFS('3. Monthly'!$A$4:$A$203,$A5,'3. Monthly'!$C$4:$C$203,$B5,'3. Monthly'!$E$4:$E$203,">0")>0,"Yes","No")) | V5: =IF($A5="","No",IF(COUNTIFS('3. Monthly'!$A$4:$A$203,$A5,'3. Monthly'!$C$4:$C$203,$B5,'3. Monthly'!$I$4:$I$203,">0")>0,"Yes","No")) | W5: =IF($A5="","No",IF(COUNTIFS('3. Monthly'!$A$4:$A$203,$A5,'3. Monthly'!$C$4:$C$203,$B5,'3. Monthly'!$K$4:$K$203,">=0",'3. Monthly'!$L$4:$L$203,">0")>0,"Yes","No")) | X5: =IF($A5="","No",IF(COUNTIFS('3. Monthly'!$A$4:$A$203,$A5,'3. Monthly'!$C$4:$C$203,$B5,'3. Monthly'!$J$4:$J$203,">=0",'3. Monthly'!$K$4:$K$203,">=0",'3. Monthly'!$M$4:$M$203,">=0",'3. Monthly'!$N$4:$N$203,">=0",'3. Monthly'!$L$4:$L$203,">0")>0,"Yes","No")) | Y5: =IF($A5="","No",IF(COUNTIFS('3. Monthly'!$A$4:$A$203,$A5,'3. Monthly'!$C$4:$C$203,$B5,'3. Monthly'!$O$4:$O$203,">0")>0,"Yes","No")) | Z5: =IF($A5="","No",IF(COUNTIFS('3. Monthly'!$A$4:$A$203,$A5,'3. Monthly'!$C$4:$C$203,$B5,'3. Monthly'!$Q$4:$Q$203,">=0",'3. Monthly'!$G$4:$G$203,">0")>0,"Yes","No")) | AA5: =IF($A5="","No",IF(COUNTIFS('3. Monthly'!$A$4:$A$203,$A5,'3. Monthly'!$C$4:$C$203,$B5,'3. Monthly'!$H$4:$H$203,">0")>0,"Yes","No")) | AB5: =IF($A5="","No",IF(COUNTIFS('3. Monthly'!$A$4:$A$203,$A5,'3. Monthly'!$C$4:$C$203,$B5,'3. Monthly'!$U$4:$U$203,">=0",'3. Monthly'!$V$4:$V$203,">=0",'3. Monthly'!$H$4:$H$203,">0")>0,"Yes","No"))
A6: ='4. Quarterly'!A6 | B6: ='4. Quarterly'!B6 | C6: =IFERROR(VLOOKUP($A6,'2. Projects'!$A$3:$B$20,2,0),"") | D6: =IF($A6="","",IFERROR(AVERAGEIFS('5. Metrics'!$D$4:$D$203,'5. Metrics'!$A$4:$A$203,$A6,'5. Metrics'!$C$4:$C$203,$B6),"")) | E6: =IF($A6="","",IFERROR(AVERAGEIFS('5. Metrics'!$E$4:$E$203,'5. Metrics'!$A$4:$A$203,$A6,'5. Metrics'!$C$4:$C$203,$B6),"")) | F6: =IF($A6="","",IFERROR(AVERAGEIFS('5. Metrics'!$F$4:$F$203,'5. Metrics'!$A$4:$A$203,$A6,'5. Metrics'!$C$4:$C$203,$B6),"")) | G6: =IF($A6="","",IFERROR(AVERAGEIFS('5. Metrics'!$I$4:$I$203,'5. Metrics'!$A$4:$A$203,$A6,'5. Metrics'!$C$4:$C$203,$B6),"")) | H6: =IF($A6="","",IFERROR(AVERAGEIFS('5. Metrics'!$L$4:$L$203,'5. Metrics'!$A$4:$A$203,$A6,'5. Metrics'!$C$4:$C$203,$B6),"")) | I6: =IF($A6="","",IFERROR(AVERAGEIFS('5. Metrics'!$M$4:$M$203,'5. Metrics'!$A$4:$A$203,$A6,'5. Metrics'!$C$4:$C$203,$B6),"")) | J6: =IF($A6="","",IFERROR(AVERAGEIFS('5. Metrics'!$N$4:$N$203,'5. Metrics'!$A$4:$A$203,$A6,'5. Metrics'!$C$4:$C$203,$B6),"")) | K6: =IF($A6="","",IFERROR(AVERAGEIFS('5. Metrics'!$P$4:$P$203,'5. Metrics'!$A$4:$A$203,$A6,'5. Metrics'!$C$4:$C$203,$B6),"")) | L6: =IF($A6="","",IFERROR(AVERAGEIFS('5. Metrics'!$Q$4:$Q$203,'5. Metrics'!$A$4:$A$203,$A6,'5. Metrics'!$C$4:$C$203,$B6),"")) | M6: =IF($A6="","",IFERROR(AVERAGEIFS('5. Metrics'!$R$4:$R$203,'5. Metrics'!$A$4:$A$203,$A6,'5. Metrics'!$C$4:$C$203,$B6),"")) | N6: =IF($A6="","",IF('4. Quarterly'!L6="Yes",5,IF(AND(ISNUMBER(E6),E6>'10. Thresholds'!$B$4,V6="Yes"),4,IF(AND('4. Quarterly'!K6="Yes",ISNUMBER(E6),E6>='10. Thresholds'!$B$3),3,IF(AND(U6="Yes",ISNUMBER(D6),D6>='10. Thresholds'!$B$5),2,1))))) | O6: =IF($A6="","",IF(AND('4. Quarterly'!P6="Yes",'4. Quarterly'!Q6="Yes",'4. Quarterly'!M6="Yes",'4. Quarterly'!N6="Yes",'4. Quarterly'!O6="Yes",X6="Yes",Y6="Yes"),5,IF(AND('4. Quarterly'!M6="Yes",'4. Quarterly'!N6="Yes",'4. Quarterly'!O6="Yes",X6="Yes",Y6="Yes"),4,IF(AND(X6="Yes",Y6="Yes"),3,IF(W6="Yes",2,1))))) | P6: =IF($A6="","",IF(AND('4. Quarterly'!V6="Yes",'4. Quarterly'!W6="Yes",'4. Quarterly'!X6="Yes",'4. Quarterly'!S6="Yes",'4. Quarterly'!T6="Yes",'4. Quarterly'!U6="Yes",'4. Quarterly'!E6="Yes",Z6="Yes",'4. Quarterly'!R6="Yes"),5,IF(AND('4. Quarterly'!S6="Yes",'4. Quarterly'!T6="Yes",'4. Quarterly'!U6="Yes",'4. Quarterly'!E6="Yes",Z6="Yes",'4. Quarterly'!R6="Yes"),4,IF(AND('4. Quarterly'!E6="Yes",Z6="Yes",'4. Quarterly'!R6="Yes"),3,IF(OR(Z6="Yes",'4. Quarterly'!R6="Yes",'4. Quarterly'!E6="Yes"),2,1))))) | Q6: =IF($A6="","",IF(AA6<>"Yes",1,IF(AB6<>"Yes",2,IF(AND('4. Quarterly'!AA6="Yes",'4. Quarterly'!Y6="Yes",'4. Quarterly'!Z6="Yes",ISNUMBER(M6),M6>='10. Thresholds'!$B$7,ISNUMBER(L6),L6<='10. Thresholds'!$B$8),5,IF(AND('4. Quarterly'!Y6="Yes",'4. Quarterly'!Z6="Yes",ISNUMBER(M6),M6>='10. Thresholds'!$B$6),4,3))))) | R6: =IF($A6="","",IF(AND('4. Quarterly'!C6="Yes",'4. Quarterly'!D6="Yes",'4. Quarterly'!E6="Yes",'4. Quarterly'!F6="Yes",'4. Quarterly'!G6="Yes",'4. Quarterly'!H6="Yes",'4. Quarterly'!I6="Yes",'4. Quarterly'!J6="Yes"),5,IF(AND('4. Quarterly'!C6="Yes",'4. Quarterly'!D6="Yes",'4. Quarterly'!E6="Yes",'4. Quarterly'!F6="Yes",'4. Quarterly'!G6="Yes"),4,IF(AND('4. Quarterly'!C6="Yes",'4. Quarterly'!D6="Yes",'4. Quarterly'!E6="Yes"),3,IF(COUNTIF('4. Quarterly'!C6:J6,"Yes")>=2,2,1))))) | S6: =IF($A6="","",MIN(R6,P6,ROUND(AVERAGE(N6,O6,P6,Q6,R6),0))) | T6: =IF($A6="","",$A6&"|"&$B6) | U6: =IF($A6="","No",IF(COUNTIFS('3. Monthly'!$A$4:$A$203,$A6,'3. Monthly'!$C$4:$C$203,$B6,'3. Monthly'!$E$4:$E$203,">0")>0,"Yes","No")) | V6: =IF($A6="","No",IF(COUNTIFS('3. Monthly'!$A$4:$A$203,$A6,'3. Monthly'!$C$4:$C$203,$B6,'3. Monthly'!$I$4:$I$203,">0")>0,"Yes","No")) | W6: =IF($A6="","No",IF(COUNTIFS('3. Monthly'!$A$4:$A$203,$A6,'3. Monthly'!$C$4:$C$203,$B6,'3. Monthly'!$K$4:$K$203,">=0",'3. Monthly'!$L$4:$L$203,">0")>0,"Yes","No")) | X6: =IF($A6="","No",IF(COUNTIFS('3. Monthly'!$A$4:$A$203,$A6,'3. Monthly'!$C$4:$C$203,$B6,'3. Monthly'!$J$4:$J$203,">=0",'3. Monthly'!$K$4:$K$203,">=0",'3. Monthly'!$M$4:$M$203,">=0",'3. Monthly'!$N$4:$N$203,">=0",'3. Monthly'!$L$4:$L$203,">0")>0,"Yes","No")) | Y6: =IF($A6="","No",IF(COUNTIFS('3. Monthly'!$A$4:$A$203,$A6,'3. Monthly'!$C$4:$C$203,$B6,'3. Monthly'!$O$4:$O$203,">0")>0,"Yes","No")) | Z6: =IF($A6="","No",IF(COUNTIFS('3. Monthly'!$A$4:$A$203,$A6,'3. Monthly'!$C$4:$C$203,$B6,'3. Monthly'!$Q$4:$Q$203,">=0",'3. Monthly'!$G$4:$G$203,">0")>0,"Yes","No")) | AA6: =IF($A6="","No",IF(COUNTIFS('3. Monthly'!$A$4:$A$203,$A6,'3. Monthly'!$C$4:$C$203,$B6,'3. Monthly'!$H$4:$H$203,">0")>0,"Yes","No")) | AB6: =IF($A6="","No",IF(COUNTIFS('3. Monthly'!$A$4:$A$203,$A6,'3. Monthly'!$C$4:$C$203,$B6,'3. Monthly'!$U$4:$U$203,">=0",'3. Monthly'!$V$4:$V$203,">=0",'3. Monthly'!$H$4:$H$203,">0")>0,"Yes","No"))
A7: ='4. Quarterly'!A7 | B7: ='4. Quarterly'!B7 | C7: =IFERROR(VLOOKUP($A7,'2. Projects'!$A$3:$B$20,2,0),"") | D7: =IF($A7="","",IFERROR(AVERAGEIFS('5. Metrics'!$D$4:$D$203,'5. Metrics'!$A$4:$A$203,$A7,'5. Metrics'!$C$4:$C$203,$B7),"")) | E7: =IF($A7="","",IFERROR(AVERAGEIFS('5. Metrics'!$E$4:$E$203,'5. Metrics'!$A$4:$A$203,$A7,'5. Metrics'!$C$4:$C$203,$B7),"")) | F7: =IF($A7="","",IFERROR(AVERAGEIFS('5. Metrics'!$F$4:$F$203,'5. Metrics'!$A$4:$A$203,$A7,'5. Metrics'!$C$4:$C$203,$B7),"")) | G7: =IF($A7="","",IFERROR(AVERAGEIFS('5. Metrics'!$I$4:$I$203,'5. Metrics'!$A$4:$A$203,$A7,'5. Metrics'!$C$4:$C$203,$B7),"")) | H7: =IF($A7="","",IFERROR(AVERAGEIFS('5. Metrics'!$L$4:$L$203,'5. Metrics'!$A$4:$A$203,$A7,'5. Metrics'!$C$4:$C$203,$B7),"")) | I7: =IF($A7="","",IFERROR(AVERAGEIFS('5. Metrics'!$M$4:$M$203,'5. Metrics'!$A$4:$A$203,$A7,'5. Metrics'!$C$4:$C$203,$B7),"")) | J7: =IF($A7="","",IFERROR(AVERAGEIFS('5. Metrics'!$N$4:$N$203,'5. Metrics'!$A$4:$A$203,$A7,'5. Metrics'!$C$4:$C$203,$B7),"")) | K7: =IF($A7="","",IFERROR(AVERAGEIFS('5. Metrics'!$P$4:$P$203,'5. Metrics'!$A$4:$A$203,$A7,'5. Metrics'!$C$4:$C$203,$B7),"")) | L7: =IF($A7="","",IFERROR(AVERAGEIFS('5. Metrics'!$Q$4:$Q$203,'5. Metrics'!$A$4:$A$203,$A7,'5. Metrics'!$C$4:$C$203,$B7),"")) | M7: =IF($A7="","",IFERROR(AVERAGEIFS('5. Metrics'!$R$4:$R$203,'5. Metrics'!$A$4:$A$203,$A7,'5. Metrics'!$C$4:$C$203,$B7),"")) | N7: =IF($A7="","",IF('4. Quarterly'!L7="Yes",5,IF(AND(ISNUMBER(E7),E7>'10. Thresholds'!$B$4,V7="Yes"),4,IF(AND('4. Quarterly'!K7="Yes",ISNUMBER(E7),E7>='10. Thresholds'!$B$3),3,IF(AND(U7="Yes",ISNUMBER(D7),D7>='10. Thresholds'!$B$5),2,1))))) | O7: =IF($A7="","",IF(AND('4. Quarterly'!P7="Yes",'4. Quarterly'!Q7="Yes",'4. Quarterly'!M7="Yes",'4. Quarterly'!N7="Yes",'4. Quarterly'!O7="Yes",X7="Yes",Y7="Yes"),5,IF(AND('4. Quarterly'!M7="Yes",'4. Quarterly'!N7="Yes",'4. Quarterly'!O7="Yes",X7="Yes",Y7="Yes"),4,IF(AND(X7="Yes",Y7="Yes"),3,IF(W7="Yes",2,1))))) | P7: =IF($A7="","",IF(AND('4. Quarterly'!V7="Yes",'4. Quarterly'!W7="Yes",'4. Quarterly'!X7="Yes",'4. Quarterly'!S7="Yes",'4. Quarterly'!T7="Yes",'4. Quarterly'!U7="Yes",'4. Quarterly'!E7="Yes",Z7="Yes",'4. Quarterly'!R7="Yes"),5,IF(AND('4. Quarterly'!S7="Yes",'4. Quarterly'!T7="Yes",'4. Quarterly'!U7="Yes",'4. Quarterly'!E7="Yes",Z7="Yes",'4. Quarterly'!R7="Yes"),4,IF(AND('4. Quarterly'!E7="Yes",Z7="Yes",'4. Quarterly'!R7="Yes"),3,IF(OR(Z7="Yes",'4. Quarterly'!R7="Yes",'4. Quarterly'!E7="Yes"),2,1))))) | Q7: =IF($A7="","",IF(AA7<>"Yes",1,IF(AB7<>"Yes",2,IF(AND('4. Quarterly'!AA7="Yes",'4. Quarterly'!Y7="Yes",'4. Quarterly'!Z7="Yes",ISNUMBER(M7),M7>='10. Thresholds'!$B$7,ISNUMBER(L7),L7<='10. Thresholds'!$B$8),5,IF(AND('4. Quarterly'!Y7="Yes",'4. Quarterly'!Z7="Yes",ISNUMBER(M7),M7>='10. Thresholds'!$B$6),4,3))))) | R7: =IF($A7="","",IF(AND('4. Quarterly'!C7="Yes",'4. Quarterly'!D7="Yes",'4. Quarterly'!E7="Yes",'4. Quarterly'!F7="Yes",'4. Quarterly'!G7="Yes",'4. Quarterly'!H7="Yes",'4. Quarterly'!I7="Yes",'4. Quarterly'!J7="Yes"),5,IF(AND('4. Quarterly'!C7="Yes",'4. Quarterly'!D7="Yes",'4. Quarterly'!E7="Yes",'4. Quarterly'!F7="Yes",'4. Quarterly'!G7="Yes"),4,IF(AND('4. Quarterly'!C7="Yes",'4. Quarterly'!D7="Yes",'4. Quarterly'!E7="Yes"),3,IF(COUNTIF('4. Quarterly'!C7:J7,"Yes")>=2,2,1))))) | S7: =IF($A7="","",MIN(R7,P7,ROUND(AVERAGE(N7,O7,P7,Q7,R7),0))) | T7: =IF($A7="","",$A7&"|"&$B7) | U7: =IF($A7="","No",IF(COUNTIFS('3. Monthly'!$A$4:$A$203,$A7,'3. Monthly'!$C$4:$C$203,$B7,'3. Monthly'!$E$4:$E$203,">0")>0,"Yes","No")) | V7: =IF($A7="","No",IF(COUNTIFS('3. Monthly'!$A$4:$A$203,$A7,'3. Monthly'!$C$4:$C$203,$B7,'3. Monthly'!$I$4:$I$203,">0")>0,"Yes","No")) | W7: =IF($A7="","No",IF(COUNTIFS('3. Monthly'!$A$4:$A$203,$A7,'3. Monthly'!$C$4:$C$203,$B7,'3. Monthly'!$K$4:$K$203,">=0",'3. Monthly'!$L$4:$L$203,">0")>0,"Yes","No")) | X7: =IF($A7="","No",IF(COUNTIFS('3. Monthly'!$A$4:$A$203,$A7,'3. Monthly'!$C$4:$C$203,$B7,'3. Monthly'!$J$4:$J$203,">=0",'3. Monthly'!$K$4:$K$203,">=0",'3. Monthly'!$M$4:$M$203,">=0",'3. Monthly'!$N$4:$N$203,">=0",'3. Monthly'!$L$4:$L$203,">0")>0,"Yes","No")) | Y7: =IF($A7="","No",IF(COUNTIFS('3. Monthly'!$A$4:$A$203,$A7,'3. Monthly'!$C$4:$C$203,$B7,'3. Monthly'!$O$4:$O$203,">0")>0,"Yes","No")) | Z7: =IF($A7="","No",IF(COUNTIFS('3. Monthly'!$A$4:$A$203,$A7,'3. Monthly'!$C$4:$C$203,$B7,'3. Monthly'!$Q$4:$Q$203,">=0",'3. Monthly'!$G$4:$G$203,">0")>0,"Yes","No")) | AA7: =IF($A7="","No",IF(COUNTIFS('3. Monthly'!$A$4:$A$203,$A7,'3. Monthly'!$C$4:$C$203,$B7,'3. Monthly'!$H$4:$H$203,">0")>0,"Yes","No")) | AB7: =IF($A7="","No",IF(COUNTIFS('3. Monthly'!$A$4:$A$203,$A7,'3. Monthly'!$C$4:$C$203,$B7,'3. Monthly'!$U$4:$U$203,">=0",'3. Monthly'!$V$4:$V$203,">=0",'3. Monthly'!$H$4:$H$203,">0")>0,"Yes","No"))
A8: ='4. Quarterly'!A8 | B8: ='4. Quarterly'!B8 | C8: =IFERROR(VLOOKUP($A8,'2. Projects'!$A$3:$B$20,2,0),"") | D8: =IF($A8="","",IFERROR(AVERAGEIFS('5. Metrics'!$D$4:$D$203,'5. Metrics'!$A$4:$A$203,$A8,'5. Metrics'!$C$4:$C$203,$B8),"")) | E8: =IF($A8="","",IFERROR(AVERAGEIFS('5. Metrics'!$E$4:$E$203,'5. Metrics'!$A$4:$A$203,$A8,'5. Metrics'!$C$4:$C$203,$B8),"")) | F8: =IF($A8="","",IFERROR(AVERAGEIFS('5. Metrics'!$F$4:$F$203,'5. Metrics'!$A$4:$A$203,$A8,'5. Metrics'!$C$4:$C$203,$B8),"")) | G8: =IF($A8="","",IFERROR(AVERAGEIFS('5. Metrics'!$I$4:$I$203,'5. Metrics'!$A$4:$A$203,$A8,'5. Metrics'!$C$4:$C$203,$B8),"")) | H8: =IF($A8="","",IFERROR(AVERAGEIFS('5. Metrics'!$L$4:$L$203,'5. Metrics'!$A$4:$A$203,$A8,'5. Metrics'!$C$4:$C$203,$B8),"")) | I8: =IF($A8="","",IFERROR(AVERAGEIFS('5. Metrics'!$M$4:$M$203,'5. Metrics'!$A$4:$A$203,$A8,'5. Metrics'!$C$4:$C$203,$B8),"")) | J8: =IF($A8="","",IFERROR(AVERAGEIFS('5. Metrics'!$N$4:$N$203,'5. Metrics'!$A$4:$A$203,$A8,'5. Metrics'!$C$4:$C$203,$B8),"")) | K8: =IF($A8="","",IFERROR(AVERAGEIFS('5. Metrics'!$P$4:$P$203,'5. Metrics'!$A$4:$A$203,$A8,'5. Metrics'!$C$4:$C$203,$B8),"")) | L8: =IF($A8="","",IFERROR(AVERAGEIFS('5. Metrics'!$Q$4:$Q$203,'5. Metrics'!$A$4:$A$203,$A8,'5. Metrics'!$C$4:$C$203,$B8),"")) | M8: =IF($A8="","",IFERROR(AVERAGEIFS('5. Metrics'!$R$4:$R$203,'5. Metrics'!$A$4:$A$203,$A8,'5. Metrics'!$C$4:$C$203,$B8),"")) | N8: =IF($A8="","",IF('4. Quarterly'!L8="Yes",5,IF(AND(ISNUMBER(E8),E8>'10. Thresholds'!$B$4,V8="Yes"),4,IF(AND('4. Quarterly'!K8="Yes",ISNUMBER(E8),E8>='10. Thresholds'!$B$3),3,IF(AND(U8="Yes",ISNUMBER(D8),D8>='10. Thresholds'!$B$5),2,1))))) | O8: =IF($A8="","",IF(AND('4. Quarterly'!P8="Yes",'4. Quarterly'!Q8="Yes",'4. Quarterly'!M8="Yes",'4. Quarterly'!N8="Yes",'4. Quarterly'!O8="Yes",X8="Yes",Y8="Yes"),5,IF(AND('4. Quarterly'!M8="Yes",'4. Quarterly'!N8="Yes",'4. Quarterly'!O8="Yes",X8="Yes",Y8="Yes"),4,IF(AND(X8="Yes",Y8="Yes"),3,IF(W8="Yes",2,1))))) | P8: =IF($A8="","",IF(AND('4. Quarterly'!V8="Yes",'4. Quarterly'!W8="Yes",'4. Quarterly'!X8="Yes",'4. Quarterly'!S8="Yes",'4. Quarterly'!T8="Yes",'4. Quarterly'!U8="Yes",'4. Quarterly'!E8="Yes",Z8="Yes",'4. Quarterly'!R8="Yes"),5,IF(AND('4. Quarterly'!S8="Yes",'4. Quarterly'!T8="Yes",'4. Quarterly'!U8="Yes",'4. Quarterly'!E8="Yes",Z8="Yes",'4. Quarterly'!R8="Yes"),4,IF(AND('4. Quarterly'!E8="Yes",Z8="Yes",'4. Quarterly'!R8="Yes"),3,IF(OR(Z8="Yes",'4. Quarterly'!R8="Yes",'4. Quarterly'!E8="Yes"),2,1))))) | Q8: =IF($A8="","",IF(AA8<>"Yes",1,IF(AB8<>"Yes",2,IF(AND('4. Quarterly'!AA8="Yes",'4. Quarterly'!Y8="Yes",'4. Quarterly'!Z8="Yes",ISNUMBER(M8),M8>='10. Thresholds'!$B$7,ISNUMBER(L8),L8<='10. Thresholds'!$B$8),5,IF(AND('4. Quarterly'!Y8="Yes",'4. Quarterly'!Z8="Yes",ISNUMBER(M8),M8>='10. Thresholds'!$B$6),4,3))))) | R8: =IF($A8="","",IF(AND('4. Quarterly'!C8="Yes",'4. Quarterly'!D8="Yes",'4. Quarterly'!E8="Yes",'4. Quarterly'!F8="Yes",'4. Quarterly'!G8="Yes",'4. Quarterly'!H8="Yes",'4. Quarterly'!I8="Yes",'4. Quarterly'!J8="Yes"),5,IF(AND('4. Quarterly'!C8="Yes",'4. Quarterly'!D8="Yes",'4. Quarterly'!E8="Yes",'4. Quarterly'!F8="Yes",'4. Quarterly'!G8="Yes"),4,IF(AND('4. Quarterly'!C8="Yes",'4. Quarterly'!D8="Yes",'4. Quarterly'!E8="Yes"),3,IF(COUNTIF('4. Quarterly'!C8:J8,"Yes")>=2,2,1))))) | S8: =IF($A8="","",MIN(R8,P8,ROUND(AVERAGE(N8,O8,P8,Q8,R8),0))) | T8: =IF($A8="","",$A8&"|"&$B8) | U8: =IF($A8="","No",IF(COUNTIFS('3. Monthly'!$A$4:$A$203,$A8,'3. Monthly'!$C$4:$C$203,$B8,'3. Monthly'!$E$4:$E$203,">0")>0,"Yes","No")) | V8: =IF($A8="","No",IF(COUNTIFS('3. Monthly'!$A$4:$A$203,$A8,'3. Monthly'!$C$4:$C$203,$B8,'3. Monthly'!$I$4:$I$203,">0")>0,"Yes","No")) | W8: =IF($A8="","No",IF(COUNTIFS('3. Monthly'!$A$4:$A$203,$A8,'3. Monthly'!$C$4:$C$203,$B8,'3. Monthly'!$K$4:$K$203,">=0",'3. Monthly'!$L$4:$L$203,">0")>0,"Yes","No")) | X8: =IF($A8="","No",IF(COUNTIFS('3. Monthly'!$A$4:$A$203,$A8,'3. Monthly'!$C$4:$C$203,$B8,'3. Monthly'!$J$4:$J$203,">=0",'3. Monthly'!$K$4:$K$203,">=0",'3. Monthly'!$M$4:$M$203,">=0",'3. Monthly'!$N$4:$N$203,">=0",'3. Monthly'!$L$4:$L$203,">0")>0,"Yes","No")) | Y8: =IF($A8="","No",IF(COUNTIFS('3. Monthly'!$A$4:$A$203,$A8,'3. Monthly'!$C$4:$C$203,$B8,'3. Monthly'!$O$4:$O$203,">0")>0,"Yes","No")) | Z8: =IF($A8="","No",IF(COUNTIFS('3. Monthly'!$A$4:$A$203,$A8,'3. Monthly'!$C$4:$C$203,$B8,'3. Monthly'!$Q$4:$Q$203,">=0",'3. Monthly'!$G$4:$G$203,">0")>0,"Yes","No")) | AA8: =IF($A8="","No",IF(COUNTIFS('3. Monthly'!$A$4:$A$203,$A8,'3. Monthly'!$C$4:$C$203,$B8,'3. Monthly'!$H$4:$H$203,">0")>0,"Yes","No")) | AB8: =IF($A8="","No",IF(COUNTIFS('3. Monthly'!$A$4:$A$203,$A8,'3. Monthly'!$C$4:$C$203,$B8,'3. Monthly'!$U$4:$U$203,">=0",'3. Monthly'!$V$4:$V$203,">=0",'3. Monthly'!$H$4:$H$203,">0")>0,"Yes","No"))
A9: ='4. Quarterly'!A9 | B9: ='4. Quarterly'!B9 | C9: =IFERROR(VLOOKUP($A9,'2. Projects'!$A$3:$B$20,2,0),"") | D9: =IF($A9="","",IFERROR(AVERAGEIFS('5. Metrics'!$D$4:$D$203,'5. Metrics'!$A$4:$A$203,$A9,'5. Metrics'!$C$4:$C$203,$B9),"")) | E9: =IF($A9="","",IFERROR(AVERAGEIFS('5. Metrics'!$E$4:$E$203,'5. Metrics'!$A$4:$A$203,$A9,'5. Metrics'!$C$4:$C$203,$B9),"")) | F9: =IF($A9="","",IFERROR(AVERAGEIFS('5. Metrics'!$F$4:$F$203,'5. Metrics'!$A$4:$A$203,$A9,'5. Metrics'!$C$4:$C$203,$B9),"")) | G9: =IF($A9="","",IFERROR(AVERAGEIFS('5. Metrics'!$I$4:$I$203,'5. Metrics'!$A$4:$A$203,$A9,'5. Metrics'!$C$4:$C$203,$B9),"")) | H9: =IF($A9="","",IFERROR(AVERAGEIFS('5. Metrics'!$L$4:$L$203,'5. Metrics'!$A$4:$A$203,$A9,'5. Metrics'!$C$4:$C$203,$B9),"")) | I9: =IF($A9="","",IFERROR(AVERAGEIFS('5. Metrics'!$M$4:$M$203,'5. Metrics'!$A$4:$A$203,$A9,'5. Metrics'!$C$4:$C$203,$B9),"")) | J9: =IF($A9="","",IFERROR(AVERAGEIFS('5. Metrics'!$N$4:$N$203,'5. Metrics'!$A$4:$A$203,$A9,'5. Metrics'!$C$4:$C$203,$B9),"")) | K9: =IF($A9="","",IFERROR(AVERAGEIFS('5. Metrics'!$P$4:$P$203,'5. Metrics'!$A$4:$A$203,$A9,'5. Metrics'!$C$4:$C$203,$B9),"")) | L9: =IF($A9="","",IFERROR(AVERAGEIFS('5. Metrics'!$Q$4:$Q$203,'5. Metrics'!$A$4:$A$203,$A9,'5. Metrics'!$C$4:$C$203,$B9),"")) | M9: =IF($A9="","",IFERROR(AVERAGEIFS('5. Metrics'!$R$4:$R$203,'5. Metrics'!$A$4:$A$203,$A9,'5. Metrics'!$C$4:$C$203,$B9),"")) | N9: =IF($A9="","",IF('4. Quarterly'!L9="Yes",5,IF(AND(ISNUMBER(E9),E9>'10. Thresholds'!$B$4,V9="Yes"),4,IF(AND('4. Quarterly'!K9="Yes",ISNUMBER(E9),E9>='10. Thresholds'!$B$3),3,IF(AND(U9="Yes",ISNUMBER(D9),D9>='10. Thresholds'!$B$5),2,1))))) | O9: =IF($A9="","",IF(AND('4. Quarterly'!P9="Yes",'4. Quarterly'!Q9="Yes",'4. Quarterly'!M9="Yes",'4. Quarterly'!N9="Yes",'4. Quarterly'!O9="Yes",X9="Yes",Y9="Yes"),5,IF(AND('4. Quarterly'!M9="Yes",'4. Quarterly'!N9="Yes",'4. Quarterly'!O9="Yes",X9="Yes",Y9="Yes"),4,IF(AND(X9="Yes",Y9="Yes"),3,IF(W9="Yes",2,1))))) | P9: =IF($A9="","",IF(AND('4. Quarterly'!V9="Yes",'4. Quarterly'!W9="Yes",'4. Quarterly'!X9="Yes",'4. Quarterly'!S9="Yes",'4. Quarterly'!T9="Yes",'4. Quarterly'!U9="Yes",'4. Quarterly'!E9="Yes",Z9="Yes",'4. Quarterly'!R9="Yes"),5,IF(AND('4. Quarterly'!S9="Yes",'4. Quarterly'!T9="Yes",'4. Quarterly'!U9="Yes",'4. Quarterly'!E9="Yes",Z9="Yes",'4. Quarterly'!R9="Yes"),4,IF(AND('4. Quarterly'!E9="Yes",Z9="Yes",'4. Quarterly'!R9="Yes"),3,IF(OR(Z9="Yes",'4. Quarterly'!R9="Yes",'4. Quarterly'!E9="Yes"),2,1))))) | Q9: =IF($A9="","",IF(AA9<>"Yes",1,IF(AB9<>"Yes",2,IF(AND('4. Quarterly'!AA9="Yes",'4. Quarterly'!Y9="Yes",'4. Quarterly'!Z9="Yes",ISNUMBER(M9),M9>='10. Thresholds'!$B$7,ISNUMBER(L9),L9<='10. Thresholds'!$B$8),5,IF(AND('4. Quarterly'!Y9="Yes",'4. Quarterly'!Z9="Yes",ISNUMBER(M9),M9>='10. Thresholds'!$B$6),4,3))))) | R9: =IF($A9="","",IF(AND('4. Quarterly'!C9="Yes",'4. Quarterly'!D9="Yes",'4. Quarterly'!E9="Yes",'4. Quarterly'!F9="Yes",'4. Quarterly'!G9="Yes",'4. Quarterly'!H9="Yes",'4. Quarterly'!I9="Yes",'4. Quarterly'!J9="Yes"),5,IF(AND('4. Quarterly'!C9="Yes",'4. Quarterly'!D9="Yes",'4. Quarterly'!E9="Yes",'4. Quarterly'!F9="Yes",'4. Quarterly'!G9="Yes"),4,IF(AND('4. Quarterly'!C9="Yes",'4. Quarterly'!D9="Yes",'4. Quarterly'!E9="Yes"),3,IF(COUNTIF('4. Quarterly'!C9:J9,"Yes")>=2,2,1))))) | S9: =IF($A9="","",MIN(R9,P9,ROUND(AVERAGE(N9,O9,P9,Q9,R9),0))) | T9: =IF($A9="","",$A9&"|"&$B9) | U9: =IF($A9="","No",IF(COUNTIFS('3. Monthly'!$A$4:$A$203,$A9,'3. Monthly'!$C$4:$C$203,$B9,'3. Monthly'!$E$4:$E$203,">0")>0,"Yes","No")) | V9: =IF($A9="","No",IF(COUNTIFS('3. Monthly'!$A$4:$A$203,$A9,'3. Monthly'!$C$4:$C$203,$B9,'3. Monthly'!$I$4:$I$203,">0")>0,"Yes","No")) | W9: =IF($A9="","No",IF(COUNTIFS('3. Monthly'!$A$4:$A$203,$A9,'3. Monthly'!$C$4:$C$203,$B9,'3. Monthly'!$K$4:$K$203,">=0",'3. Monthly'!$L$4:$L$203,">0")>0,"Yes","No")) | X9: =IF($A9="","No",IF(COUNTIFS('3. Monthly'!$A$4:$A$203,$A9,'3. Monthly'!$C$4:$C$203,$B9,'3. Monthly'!$J$4:$J$203,">=0",'3. Monthly'!$K$4:$K$203,">=0",'3. Monthly'!$M$4:$M$203,">=0",'3. Monthly'!$N$4:$N$203,">=0",'3. Monthly'!$L$4:$L$203,">0")>0,"Yes","No")) | Y9: =IF($A9="","No",IF(COUNTIFS('3. Monthly'!$A$4:$A$203,$A9,'3. Monthly'!$C$4:$C$203,$B9,'3. Monthly'!$O$4:$O$203,">0")>0,"Yes","No")) | Z9: =IF($A9="","No",IF(COUNTIFS('3. Monthly'!$A$4:$A$203,$A9,'3. Monthly'!$C$4:$C$203,$B9,'3. Monthly'!$Q$4:$Q$203,">=0",'3. Monthly'!$G$4:$G$203,">0")>0,"Yes","No")) | AA9: =IF($A9="","No",IF(COUNTIFS('3. Monthly'!$A$4:$A$203,$A9,'3. Monthly'!$C$4:$C$203,$B9,'3. Monthly'!$H$4:$H$203,">0")>0,"Yes","No")) | AB9: =IF($A9="","No",IF(COUNTIFS('3. Monthly'!$A$4:$A$203,$A9,'3. Monthly'!$C$4:$C$203,$B9,'3. Monthly'!$U$4:$U$203,">=0",'3. Monthly'!$V$4:$V$203,">=0",'3. Monthly'!$H$4:$H$203,">0")>0,"Yes","No"))
A10: ='4. Quarterly'!A10 | B10: ='4. Quarterly'!B10 | C10: =IFERROR(VLOOKUP($A10,'2. Projects'!$A$3:$B$20,2,0),"") | D10: =IF($A10="","",IFERROR(AVERAGEIFS('5. Metrics'!$D$4:$D$203,'5. Metrics'!$A$4:$A$203,$A10,'5. Metrics'!$C$4:$C$203,$B10),"")) | E10: =IF($A10="","",IFERROR(AVERAGEIFS('5. Metrics'!$E$4:$E$203,'5. Metrics'!$A$4:$A$203,$A10,'5. Metrics'!$C$4:$C$203,$B10),"")) | F10: =IF($A10="","",IFERROR(AVERAGEIFS('5. Metrics'!$F$4:$F$203,'5. Metrics'!$A$4:$A$203,$A10,'5. Metrics'!$C$4:$C$203,$B10),"")) | G10: =IF($A10="","",IFERROR(AVERAGEIFS('5. Metrics'!$I$4:$I$203,'5. Metrics'!$A$4:$A$203,$A10,'5. Metrics'!$C$4:$C$203,$B10),"")) | H10: =IF($A10="","",IFERROR(AVERAGEIFS('5. Metrics'!$L$4:$L$203,'5. Metrics'!$A$4:$A$203,$A10,'5. Metrics'!$C$4:$C$203,$B10),"")) | I10: =IF($A10="","",IFERROR(AVERAGEIFS('5. Metrics'!$M$4:$M$203,'5. Metrics'!$A$4:$A$203,$A10,'5. Metrics'!$C$4:$C$203,$B10),"")) | J10: =IF($A10="","",IFERROR(AVERAGEIFS('5. Metrics'!$N$4:$N$203,'5. Metrics'!$A$4:$A$203,$A10,'5. Metrics'!$C$4:$C$203,$B10),"")) | K10: =IF($A10="","",IFERROR(AVERAGEIFS('5. Metrics'!$P$4:$P$203,'5. Metrics'!$A$4:$A$203,$A10,'5. Metrics'!$C$4:$C$203,$B10),"")) | L10: =IF($A10="","",IFERROR(AVERAGEIFS('5. Metrics'!$Q$4:$Q$203,'5. Metrics'!$A$4:$A$203,$A10,'5. Metrics'!$C$4:$C$203,$B10),"")) | M10: =IF($A10="","",IFERROR(AVERAGEIFS('5. Metrics'!$R$4:$R$203,'5. Metrics'!$A$4:$A$203,$A10,'5. Metrics'!$C$4:$C$203,$B10),"")) | N10: =IF($A10="","",IF('4. Quarterly'!L10="Yes",5,IF(AND(ISNUMBER(E10),E10>'10. Thresholds'!$B$4,V10="Yes"),4,IF(AND('4. Quarterly'!K10="Yes",ISNUMBER(E10),E10>='10. Thresholds'!$B$3),3,IF(AND(U10="Yes",ISNUMBER(D10),D10>='10. Thresholds'!$B$5),2,1))))) | O10: =IF($A10="","",IF(AND('4. Quarterly'!P10="Yes",'4. Quarterly'!Q10="Yes",'4. Quarterly'!M10="Yes",'4. Quarterly'!N10="Yes",'4. Quarterly'!O10="Yes",X10="Yes",Y10="Yes"),5,IF(AND('4. Quarterly'!M10="Yes",'4. Quarterly'!N10="Yes",'4. Quarterly'!O10="Yes",X10="Yes",Y10="Yes"),4,IF(AND(X10="Yes",Y10="Yes"),3,IF(W10="Yes",2,1))))) | P10: =IF($A10="","",IF(AND('4. Quarterly'!V10="Yes",'4. Quarterly'!W10="Yes",'4. Quarterly'!X10="Yes",'4. Quarterly'!S10="Yes",'4. Quarterly'!T10="Yes",'4. Quarterly'!U10="Yes",'4. Quarterly'!E10="Yes",Z10="Yes",'4. Quarterly'!R10="Yes"),5,IF(AND('4. Quarterly'!S10="Yes",'4. Quarterly'!T10="Yes",'4. Quarterly'!U10="Yes",'4. Quarterly'!E10="Yes",Z10="Yes",'4. Quarterly'!R10="Yes"),4,IF(AND('4. Quarterly'!E10="Yes",Z10="Yes",'4. Quarterly'!R10="Yes"),3,IF(OR(Z10="Yes",'4. Quarterly'!R10="Yes",'4. Quarterly'!E10="Yes"),2,1))))) | Q10: =IF($A10="","",IF(AA10<>"Yes",1,IF(AB10<>"Yes",2,IF(AND('4. Quarterly'!AA10="Yes",'4. Quarterly'!Y10="Yes",'4. Quarterly'!Z10="Yes",ISNUMBER(M10),M10>='10. Thresholds'!$B$7,ISNUMBER(L10),L10<='10. Thresholds'!$B$8),5,IF(AND('4. Quarterly'!Y10="Yes",'4. Quarterly'!Z10="Yes",ISNUMBER(M10),M10>='10. Thresholds'!$B$6),4,3))))) | R10: =IF($A10="","",IF(AND('4. Quarterly'!C10="Yes",'4. Quarterly'!D10="Yes",'4. Quarterly'!E10="Yes",'4. Quarterly'!F10="Yes",'4. Quarterly'!G10="Yes",'4. Quarterly'!H10="Yes",'4. Quarterly'!I10="Yes",'4. Quarterly'!J10="Yes"),5,IF(AND('4. Quarterly'!C10="Yes",'4. Quarterly'!D10="Yes",'4. Quarterly'!E10="Yes",'4. Quarterly'!F10="Yes",'4. Quarterly'!G10="Yes"),4,IF(AND('4. Quarterly'!C10="Yes",'4. Quarterly'!D10="Yes",'4. Quarterly'!E10="Yes"),3,IF(COUNTIF('4. Quarterly'!C10:J10,"Yes")>=2,2,1))))) | S10: =IF($A10="","",MIN(R10,P10,ROUND(AVERAGE(N10,O10,P10,Q10,R10),0))) | T10: =IF($A10="","",$A10&"|"&$B10) | U10: =IF($A10="","No",IF(COUNTIFS('3. Monthly'!$A$4:$A$203,$A10,'3. Monthly'!$C$4:$C$203,$B10,'3. Monthly'!$E$4:$E$203,">0")>0,"Yes","No")) | V10: =IF($A10="","No",IF(COUNTIFS('3. Monthly'!$A$4:$A$203,$A10,'3. Monthly'!$C$4:$C$203,$B10,'3. Monthly'!$I$4:$I$203,">0")>0,"Yes","No")) | W10: =IF($A10="","No",IF(COUNTIFS('3. Monthly'!$A$4:$A$203,$A10,'3. Monthly'!$C$4:$C$203,$B10,'3. Monthly'!$K$4:$K$203,">=0",'3. Monthly'!$L$4:$L$203,">0")>0,"Yes","No")) | X10: =IF($A10="","No",IF(COUNTIFS('3. Monthly'!$A$4:$A$203,$A10,'3. Monthly'!$C$4:$C$203,$B10,'3. Monthly'!$J$4:$J$203,">=0",'3. Monthly'!$K$4:$K$203,">=0",'3. Monthly'!$M$4:$M$203,">=0",'3. Monthly'!$N$4:$N$203,">=0",'3. Monthly'!$L$4:$L$203,">0")>0,"Yes","No")) | Y10: =IF($A10="","No",IF(COUNTIFS('3. Monthly'!$A$4:$A$203,$A10,'3. Monthly'!$C$4:$C$203,$B10,'3. Monthly'!$O$4:$O$203,">0")>0,"Yes","No")) | Z10: =IF($A10="","No",IF(COUNTIFS('3. Monthly'!$A$4:$A$203,$A10,'3. Monthly'!$C$4:$C$203,$B10,'3. Monthly'!$Q$4:$Q$203,">=0",'3. Monthly'!$G$4:$G$203,">0")>0,"Yes","No")) | AA10: =IF($A10="","No",IF(COUNTIFS('3. Monthly'!$A$4:$A$203,$A10,'3. Monthly'!$C$4:$C$203,$B10,'3. Monthly'!$H$4:$H$203,">0")>0,"Yes","No")) | AB10: =IF($A10="","No",IF(COUNTIFS('3. Monthly'!$A$4:$A$203,$A10,'3. Monthly'!$C$4:$C$203,$B10,'3. Monthly'!$U$4:$U$203,">=0",'3. Monthly'!$V$4:$V$203,">=0",'3. Monthly'!$H$4:$H$203,">0")>0,"Yes","No"))
A11: ='4. Quarterly'!A11 | B11: ='4. Quarterly'!B11 | C11: =IFERROR(VLOOKUP($A11,'2. Projects'!$A$3:$B$20,2,0),"") | D11: =IF($A11="","",IFERROR(AVERAGEIFS('5. Metrics'!$D$4:$D$203,'5. Metrics'!$A$4:$A$203,$A11,'5. Metrics'!$C$4:$C$203,$B11),"")) | E11: =IF($A11="","",IFERROR(AVERAGEIFS('5. Metrics'!$E$4:$E$203,'5. Metrics'!$A$4:$A$203,$A11,'5. Metrics'!$C$4:$C$203,$B11),"")) | F11: =IF($A11="","",IFERROR(AVERAGEIFS('5. Metrics'!$F$4:$F$203,'5. Metrics'!$A$4:$A$203,$A11,'5. Metrics'!$C$4:$C$203,$B11),"")) | G11: =IF($A11="","",IFERROR(AVERAGEIFS('5. Metrics'!$I$4:$I$203,'5. Metrics'!$A$4:$A$203,$A11,'5. Metrics'!$C$4:$C$203,$B11),"")) | H11: =IF($A11="","",IFERROR(AVERAGEIFS('5. Metrics'!$L$4:$L$203,'5. Metrics'!$A$4:$A$203,$A11,'5. Metrics'!$C$4:$C$203,$B11),"")) | I11: =IF($A11="","",IFERROR(AVERAGEIFS('5. Metrics'!$M$4:$M$203,'5. Metrics'!$A$4:$A$203,$A11,'5. Metrics'!$C$4:$C$203,$B11),"")) | J11: =IF($A11="","",IFERROR(AVERAGEIFS('5. Metrics'!$N$4:$N$203,'5. Metrics'!$A$4:$A$203,$A11,'5. Metrics'!$C$4:$C$203,$B11),"")) | K11: =IF($A11="","",IFERROR(AVERAGEIFS('5. Metrics'!$P$4:$P$203,'5. Metrics'!$A$4:$A$203,$A11,'5. Metrics'!$C$4:$C$203,$B11),"")) | L11: =IF($A11="","",IFERROR(AVERAGEIFS('5. Metrics'!$Q$4:$Q$203,'5. Metrics'!$A$4:$A$203,$A11,'5. Metrics'!$C$4:$C$203,$B11),"")) | M11: =IF($A11="","",IFERROR(AVERAGEIFS('5. Metrics'!$R$4:$R$203,'5. Metrics'!$A$4:$A$203,$A11,'5. Metrics'!$C$4:$C$203,$B11),"")) | N11: =IF($A11="","",IF('4. Quarterly'!L11="Yes",5,IF(AND(ISNUMBER(E11),E11>'10. Thresholds'!$B$4,V11="Yes"),4,IF(AND('4. Quarterly'!K11="Yes",ISNUMBER(E11),E11>='10. Thresholds'!$B$3),3,IF(AND(U11="Yes",ISNUMBER(D11),D11>='10. Thresholds'!$B$5),2,1))))) | O11: =IF($A11="","",IF(AND('4. Quarterly'!P11="Yes",'4. Quarterly'!Q11="Yes",'4. Quarterly'!M11="Yes",'4. Quarterly'!N11="Yes",'4. Quarterly'!O11="Yes",X11="Yes",Y11="Yes"),5,IF(AND('4. Quarterly'!M11="Yes",'4. Quarterly'!N11="Yes",'4. Quarterly'!O11="Yes",X11="Yes",Y11="Yes"),4,IF(AND(X11="Yes",Y11="Yes"),3,IF(W11="Yes",2,1))))) | P11: =IF($A11="","",IF(AND('4. Quarterly'!V11="Yes",'4. Quarterly'!W11="Yes",'4. Quarterly'!X11="Yes",'4. Quarterly'!S11="Yes",'4. Quarterly'!T11="Yes",'4. Quarterly'!U11="Yes",'4. Quarterly'!E11="Yes",Z11="Yes",'4. Quarterly'!R11="Yes"),5,IF(AND('4. Quarterly'!S11="Yes",'4. Quarterly'!T11="Yes",'4. Quarterly'!U11="Yes",'4. Quarterly'!E11="Yes",Z11="Yes",'4. Quarterly'!R11="Yes"),4,IF(AND('4. Quarterly'!E11="Yes",Z11="Yes",'4. Quarterly'!R11="Yes"),3,IF(OR(Z11="Yes",'4. Quarterly'!R11="Yes",'4. Quarterly'!E11="Yes"),2,1))))) | Q11: =IF($A11="","",IF(AA11<>"Yes",1,IF(AB11<>"Yes",2,IF(AND('4. Quarterly'!AA11="Yes",'4. Quarterly'!Y11="Yes",'4. Quarterly'!Z11="Yes",ISNUMBER(M11),M11>='10. Thresholds'!$B$7,ISNUMBER(L11),L11<='10. Thresholds'!$B$8),5,IF(AND('4. Quarterly'!Y11="Yes",'4. Quarterly'!Z11="Yes",ISNUMBER(M11),M11>='10. Thresholds'!$B$6),4,3))))) | R11: =IF($A11="","",IF(AND('4. Quarterly'!C11="Yes",'4. Quarterly'!D11="Yes",'4. Quarterly'!E11="Yes",'4. Quarterly'!F11="Yes",'4. Quarterly'!G11="Yes",'4. Quarterly'!H11="Yes",'4. Quarterly'!I11="Yes",'4. Quarterly'!J11="Yes"),5,IF(AND('4. Quarterly'!C11="Yes",'4. Quarterly'!D11="Yes",'4. Quarterly'!E11="Yes",'4. Quarterly'!F11="Yes",'4. Quarterly'!G11="Yes"),4,IF(AND('4. Quarterly'!C11="Yes",'4. Quarterly'!D11="Yes",'4. Quarterly'!E11="Yes"),3,IF(COUNTIF('4. Quarterly'!C11:J11,"Yes")>=2,2,1))))) | S11: =IF($A11="","",MIN(R11,P11,ROUND(AVERAGE(N11,O11,P11,Q11,R11),0))) | T11: =IF($A11="","",$A11&"|"&$B11) | U11: =IF($A11="","No",IF(COUNTIFS('3. Monthly'!$A$4:$A$203,$A11,'3. Monthly'!$C$4:$C$203,$B11,'3. Monthly'!$E$4:$E$203,">0")>0,"Yes","No")) | V11: =IF($A11="","No",IF(COUNTIFS('3. Monthly'!$A$4:$A$203,$A11,'3. Monthly'!$C$4:$C$203,$B11,'3. Monthly'!$I$4:$I$203,">0")>0,"Yes","No")) | W11: =IF($A11="","No",IF(COUNTIFS('3. Monthly'!$A$4:$A$203,$A11,'3. Monthly'!$C$4:$C$203,$B11,'3. Monthly'!$K$4:$K$203,">=0",'3. Monthly'!$L$4:$L$203,">0")>0,"Yes","No")) | X11: =IF($A11="","No",IF(COUNTIFS('3. Monthly'!$A$4:$A$203,$A11,'3. Monthly'!$C$4:$C$203,$B11,'3. Monthly'!$J$4:$J$203,">=0",'3. Monthly'!$K$4:$K$203,">=0",'3. Monthly'!$M$4:$M$203,">=0",'3. Monthly'!$N$4:$N$203,">=0",'3. Monthly'!$L$4:$L$203,">0")>0,"Yes","No")) | Y11: =IF($A11="","No",IF(COUNTIFS('3. Monthly'!$A$4:$A$203,$A11,'3. Monthly'!$C$4:$C$203,$B11,'3. Monthly'!$O$4:$O$203,">0")>0,"Yes","No")) | Z11: =IF($A11="","No",IF(COUNTIFS('3. Monthly'!$A$4:$A$203,$A11,'3. Monthly'!$C$4:$C$203,$B11,'3. Monthly'!$Q$4:$Q$203,">=0",'3. Monthly'!$G$4:$G$203,">0")>0,"Yes","No")) | AA11: =IF($A11="","No",IF(COUNTIFS('3. Monthly'!$A$4:$A$203,$A11,'3. Monthly'!$C$4:$C$203,$B11,'3. Monthly'!$H$4:$H$203,">0")>0,"Yes","No")) | AB11: =IF($A11="","No",IF(COUNTIFS('3. Monthly'!$A$4:$A$203,$A11,'3. Monthly'!$C$4:$C$203,$B11,'3. Monthly'!$U$4:$U$203,">=0",'3. Monthly'!$V$4:$V$203,">=0",'3. Monthly'!$H$4:$H$203,">0")>0,"Yes","No"))
